[E 11:35:22.957 NotebookApp] Exception while loading config file /mnt/iusers01/nw01/mbcxrhm2/.jupyter/jupyter_notebook_config.py
    Traceback (most recent call last):
      File "/opt/gridware/apps/binapps/anaconda/2.5.0/lib/python2.7/site-packages/traitlets/config/application.py", line 531, in _load_config_files
        config = loader.load_config()
      File "/opt/gridware/apps/binapps/anaconda/2.5.0/lib/python2.7/site-packages/traitlets/config/loader.py", line 432, in load_config
        self._read_file_as_dict()
      File "/opt/gridware/apps/binapps/anaconda/2.5.0/lib/python2.7/site-packages/traitlets/config/loader.py", line 464, in _read_file_as_dict
        py3compat.execfile(conf_filename, namespace)
      File "/opt/gridware/apps/binapps/anaconda/2.5.0/lib/python2.7/site-packages/ipython_genutils/py3compat.py", line 288, in execfile
        builtin_mod.execfile(filename, *where)
      File "/mnt/iusers01/nw01/mbcxrhm2/.jupyter/jupyter_notebook_config.py", line 1, in <module>
        f# Configuration file for jupyter-notebook.
    NameError: name 'f' is not defined
[I 11:35:25.976 NotebookApp] Serving notebooks from local directory: /mnt/iusers01/nw01/mbcxrhm2/dimer-code
[I 11:35:25.976 NotebookApp] 0 active kernels 
[I 11:35:25.976 NotebookApp] The Jupyter Notebook is running at: http://10.110.60.76:8888/
[I 11:35:25.976 NotebookApp] Use Control-C to stop this server and shut down all kernels (twice to skip confirmation).
[I 11:50:52.753 NotebookApp] 302 GET / (10.110.1.41) 0.48ms
[I 11:51:01.129 NotebookApp] Kernel started: 3f9cef16-4e2f-4483-b111-3f303e48d163
[I 11:53:01.633 NotebookApp] Saving file at /convergence_SES.ipynb
[I 11:57:01.522 NotebookApp] Saving file at /convergence_SES.ipynb
[I 11:57:20.937 NotebookApp] Saving file at /heatmap_setup.py
[I 11:58:53.392 NotebookApp] Kernel restarted: 3f9cef16-4e2f-4483-b111-3f303e48d163
[I 11:59:01.219 NotebookApp] Saving file at /convergence_SES.ipynb
[I 12:01:01.059 NotebookApp] Saving file at /convergence_SES.ipynb
[I 12:02:16.817 NotebookApp] Saving file at /phonons.py
[I 12:03:01.025 NotebookApp] Saving file at /convergence_SES.ipynb
[I 12:03:49.402 NotebookApp] Saving file at /optical.py
[I 12:03:50.788 NotebookApp] Saving file at /phonons.py
[I 12:04:05.172 NotebookApp] Saving file at /convergence_SES.ipynb
[I 12:05:01.023 NotebookApp] Saving file at /convergence_SES.ipynb
[I 12:07:01.508 NotebookApp] Saving file at /convergence_SES.ipynb
[I 12:09:01.008 NotebookApp] Saving file at /convergence_SES.ipynb
[I 12:11:01.072 NotebookApp] Saving file at /convergence_SES.ipynb
[I 12:13:01.020 NotebookApp] Saving file at /convergence_SES.ipynb
[I 12:15:01.005 NotebookApp] Saving file at /convergence_SES.ipynb
[I 12:17:00.988 NotebookApp] Saving file at /convergence_SES.ipynb
[I 12:19:00.982 NotebookApp] Saving file at /convergence_SES.ipynb
[I 12:21:00.990 NotebookApp] Saving file at /convergence_SES.ipynb
[I 12:23:00.978 NotebookApp] Saving file at /convergence_SES.ipynb
[I 12:25:01.013 NotebookApp] Saving file at /convergence_SES.ipynb
[I 12:39:00.973 NotebookApp] Saving file at /convergence_SES.ipynb
[I 12:41:01.916 NotebookApp] Saving file at /convergence_SES.ipynb
[I 12:53:28.484 NotebookApp] Saving file at /phonons.py
[I 12:53:47.290 NotebookApp] Saving file at /phonons.py
[I 12:54:04.046 NotebookApp] Saving file at /phonons.py
[I 12:55:01.429 NotebookApp] Saving file at /convergence_SES.ipynb
[I 12:55:08.200 NotebookApp] Saving file at /phonons.py
[I 12:55:10.646 NotebookApp] Saving file at /phonons.py
[I 12:55:21.564 NotebookApp] Saving file at /phonons.py
[I 12:55:45.492 NotebookApp] Saving file at /phonons.py
[I 12:56:06.738 NotebookApp] Saving file at /phonons.py
[I 12:57:00.914 NotebookApp] Saving file at /convergence_SES.ipynb
[I 13:00:56.100 NotebookApp] Saving file at /heatmap_setup.py
[I 13:21:01.669 NotebookApp] Saving file at /convergence_SES.ipynb
[I 13:25:00.883 NotebookApp] Saving file at /convergence_SES.ipynb
[I 13:27:00.932 NotebookApp] Saving file at /convergence_SES.ipynb
[I 13:27:13.331 NotebookApp] Kernel interrupted: 3f9cef16-4e2f-4483-b111-3f303e48d163
[I 13:27:28.279 NotebookApp] Saving file at /phonons.py
[I 13:27:35.667 NotebookApp] Kernel restarted: 3f9cef16-4e2f-4483-b111-3f303e48d163
Traceback (most recent call last):
  File "/opt/gridware/apps/binapps/anaconda/2.5.0/lib/python2.7/runpy.py", line 162, in _run_module_as_main
    "__main__", fname, loader, pkg_name)
  File "/opt/gridware/apps/binapps/anaconda/2.5.0/lib/python2.7/runpy.py", line 72, in _run_code
    exec code in run_globals
  File "/opt/gridware/apps/binapps/anaconda/2.5.0/lib/python2.7/site-packages/ipykernel/__main__.py", line 3, in <module>
    app.launch_new_instance()
  File "/opt/gridware/apps/binapps/anaconda/2.5.0/lib/python2.7/site-packages/traitlets/config/application.py", line 588, in launch_instance
    app.initialize(argv)
  File "<decorator-gen-121>", line 2, in initialize
  File "/opt/gridware/apps/binapps/anaconda/2.5.0/lib/python2.7/site-packages/traitlets/config/application.py", line 74, in catch_config_error
    return method(app, *args, **kwargs)
  File "/opt/gridware/apps/binapps/anaconda/2.5.0/lib/python2.7/site-packages/ipykernel/kernelapp.py", line 375, in initialize
    self.init_sockets()
  File "/opt/gridware/apps/binapps/anaconda/2.5.0/lib/python2.7/site-packages/ipykernel/kernelapp.py", line 231, in init_sockets
    self.shell_port = self._bind_socket(self.shell_socket, self.shell_port)
  File "/opt/gridware/apps/binapps/anaconda/2.5.0/lib/python2.7/site-packages/ipykernel/kernelapp.py", line 173, in _bind_socket
    s.bind("tcp://%s:%i" % (self.ip, port))
  File "zmq/backend/cython/socket.pyx", line 487, in zmq.backend.cython.socket.Socket.bind (zmq/backend/cython/socket.c:5156)
  File "zmq/backend/cython/checkrc.pxd", line 25, in zmq.backend.cython.checkrc._check_rc (zmq/backend/cython/socket.c:7535)
    raise ZMQError(errno)
ZMQError: Address already in use
[I 13:27:38.669 NotebookApp] KernelRestarter: restarting kernel (1/5)
Traceback (most recent call last):
  File "/opt/gridware/apps/binapps/anaconda/2.5.0/lib/python2.7/runpy.py", line 162, in _run_module_as_main
    "__main__", fname, loader, pkg_name)
  File "/opt/gridware/apps/binapps/anaconda/2.5.0/lib/python2.7/runpy.py", line 72, in _run_code
    exec code in run_globals
  File "/opt/gridware/apps/binapps/anaconda/2.5.0/lib/python2.7/site-packages/ipykernel/__main__.py", line 3, in <module>
    app.launch_new_instance()
  File "/opt/gridware/apps/binapps/anaconda/2.5.0/lib/python2.7/site-packages/traitlets/config/application.py", line 588, in launch_instance
    app.initialize(argv)
  File "<decorator-gen-121>", line 2, in initialize
  File "/opt/gridware/apps/binapps/anaconda/2.5.0/lib/python2.7/site-packages/traitlets/config/application.py", line 74, in catch_config_error
    return method(app, *args, **kwargs)
  File "/opt/gridware/apps/binapps/anaconda/2.5.0/lib/python2.7/site-packages/ipykernel/kernelapp.py", line 375, in initialize
    self.init_sockets()
  File "/opt/gridware/apps/binapps/anaconda/2.5.0/lib/python2.7/site-packages/ipykernel/kernelapp.py", line 231, in init_sockets
    self.shell_port = self._bind_socket(self.shell_socket, self.shell_port)
  File "/opt/gridware/apps/binapps/anaconda/2.5.0/lib/python2.7/site-packages/ipykernel/kernelapp.py", line 173, in _bind_socket
    s.bind("tcp://%s:%i" % (self.ip, port))
  File "zmq/backend/cython/socket.pyx", line 487, in zmq.backend.cython.socket.Socket.bind (zmq/backend/cython/socket.c:5156)
  File "zmq/backend/cython/checkrc.pxd", line 25, in zmq.backend.cython.checkrc._check_rc (zmq/backend/cython/socket.c:7535)
    raise ZMQError(errno)
ZMQError: Address already in use
[I 13:27:40.375 NotebookApp] Saving file at /convergence_SES.ipynb
[I 13:27:41.674 NotebookApp] KernelRestarter: restarting kernel (2/5)
Traceback (most recent call last):
  File "/opt/gridware/apps/binapps/anaconda/2.5.0/lib/python2.7/runpy.py", line 162, in _run_module_as_main
    "__main__", fname, loader, pkg_name)
  File "/opt/gridware/apps/binapps/anaconda/2.5.0/lib/python2.7/runpy.py", line 72, in _run_code
    exec code in run_globals
  File "/opt/gridware/apps/binapps/anaconda/2.5.0/lib/python2.7/site-packages/ipykernel/__main__.py", line 3, in <module>
    app.launch_new_instance()
  File "/opt/gridware/apps/binapps/anaconda/2.5.0/lib/python2.7/site-packages/traitlets/config/application.py", line 588, in launch_instance
    app.initialize(argv)
  File "<decorator-gen-121>", line 2, in initialize
  File "/opt/gridware/apps/binapps/anaconda/2.5.0/lib/python2.7/site-packages/traitlets/config/application.py", line 74, in catch_config_error
    return method(app, *args, **kwargs)
  File "/opt/gridware/apps/binapps/anaconda/2.5.0/lib/python2.7/site-packages/ipykernel/kernelapp.py", line 375, in initialize
    self.init_sockets()
  File "/opt/gridware/apps/binapps/anaconda/2.5.0/lib/python2.7/site-packages/ipykernel/kernelapp.py", line 231, in init_sockets
    self.shell_port = self._bind_socket(self.shell_socket, self.shell_port)
  File "/opt/gridware/apps/binapps/anaconda/2.5.0/lib/python2.7/site-packages/ipykernel/kernelapp.py", line 173, in _bind_socket
    s.bind("tcp://%s:%i" % (self.ip, port))
  File "zmq/backend/cython/socket.pyx", line 487, in zmq.backend.cython.socket.Socket.bind (zmq/backend/cython/socket.c:5156)
  File "zmq/backend/cython/checkrc.pxd", line 25, in zmq.backend.cython.checkrc._check_rc (zmq/backend/cython/socket.c:7535)
    raise ZMQError(errno)
ZMQError: Address already in use
[I 13:27:44.682 NotebookApp] KernelRestarter: restarting kernel (3/5)
Traceback (most recent call last):
  File "/opt/gridware/apps/binapps/anaconda/2.5.0/lib/python2.7/runpy.py", line 162, in _run_module_as_main
    "__main__", fname, loader, pkg_name)
  File "/opt/gridware/apps/binapps/anaconda/2.5.0/lib/python2.7/runpy.py", line 72, in _run_code
    exec code in run_globals
  File "/opt/gridware/apps/binapps/anaconda/2.5.0/lib/python2.7/site-packages/ipykernel/__main__.py", line 3, in <module>
    app.launch_new_instance()
  File "/opt/gridware/apps/binapps/anaconda/2.5.0/lib/python2.7/site-packages/traitlets/config/application.py", line 588, in launch_instance
    app.initialize(argv)
  File "<decorator-gen-121>", line 2, in initialize
  File "/opt/gridware/apps/binapps/anaconda/2.5.0/lib/python2.7/site-packages/traitlets/config/application.py", line 74, in catch_config_error
    return method(app, *args, **kwargs)
  File "/opt/gridware/apps/binapps/anaconda/2.5.0/lib/python2.7/site-packages/ipykernel/kernelapp.py", line 375, in initialize
    self.init_sockets()
  File "/opt/gridware/apps/binapps/anaconda/2.5.0/lib/python2.7/site-packages/ipykernel/kernelapp.py", line 231, in init_sockets
    self.shell_port = self._bind_socket(self.shell_socket, self.shell_port)
  File "/opt/gridware/apps/binapps/anaconda/2.5.0/lib/python2.7/site-packages/ipykernel/kernelapp.py", line 173, in _bind_socket
    s.bind("tcp://%s:%i" % (self.ip, port))
  File "zmq/backend/cython/socket.pyx", line 487, in zmq.backend.cython.socket.Socket.bind (zmq/backend/cython/socket.c:5156)
  File "zmq/backend/cython/checkrc.pxd", line 25, in zmq.backend.cython.checkrc._check_rc (zmq/backend/cython/socket.c:7535)
    raise ZMQError(errno)
ZMQError: Address already in use
[I 13:27:47.689 NotebookApp] KernelRestarter: restarting kernel (4/5)
Traceback (most recent call last):
  File "/opt/gridware/apps/binapps/anaconda/2.5.0/lib/python2.7/runpy.py", line 162, in _run_module_as_main
    "__main__", fname, loader, pkg_name)
  File "/opt/gridware/apps/binapps/anaconda/2.5.0/lib/python2.7/runpy.py", line 72, in _run_code
    exec code in run_globals
  File "/opt/gridware/apps/binapps/anaconda/2.5.0/lib/python2.7/site-packages/ipykernel/__main__.py", line 3, in <module>
    app.launch_new_instance()
  File "/opt/gridware/apps/binapps/anaconda/2.5.0/lib/python2.7/site-packages/traitlets/config/application.py", line 588, in launch_instance
    app.initialize(argv)
  File "<decorator-gen-121>", line 2, in initialize
  File "/opt/gridware/apps/binapps/anaconda/2.5.0/lib/python2.7/site-packages/traitlets/config/application.py", line 74, in catch_config_error
    return method(app, *args, **kwargs)
  File "/opt/gridware/apps/binapps/anaconda/2.5.0/lib/python2.7/site-packages/ipykernel/kernelapp.py", line 375, in initialize
    self.init_sockets()
  File "/opt/gridware/apps/binapps/anaconda/2.5.0/lib/python2.7/site-packages/ipykernel/kernelapp.py", line 231, in init_sockets
    self.shell_port = self._bind_socket(self.shell_socket, self.shell_port)
  File "/opt/gridware/apps/binapps/anaconda/2.5.0/lib/python2.7/site-packages/ipykernel/kernelapp.py", line 173, in _bind_socket
    s.bind("tcp://%s:%i" % (self.ip, port))
  File "zmq/backend/cython/socket.pyx", line 487, in zmq.backend.cython.socket.Socket.bind (zmq/backend/cython/socket.c:5156)
  File "zmq/backend/cython/checkrc.pxd", line 25, in zmq.backend.cython.checkrc._check_rc (zmq/backend/cython/socket.c:7535)
    raise ZMQError(errno)
ZMQError: Address already in use
[W 13:27:50.696 NotebookApp] KernelRestarter: restart failed
[W 13:27:50.697 NotebookApp] Kernel 3f9cef16-4e2f-4483-b111-3f303e48d163 died, removing from map.
[W 13:27:50.697 NotebookApp] Restarting kernel failed: 3f9cef16-4e2f-4483-b111-3f303e48d163
[E 13:27:50.698 NotebookApp] Exception restarting kernel
    Traceback (most recent call last):
      File "/opt/gridware/apps/binapps/anaconda/2.5.0/lib/python2.7/site-packages/notebook/services/kernels/handlers.py", line 88, in post
        yield gen.maybe_future(km.restart_kernel(kernel_id))
      File "/opt/gridware/apps/binapps/anaconda/2.5.0/lib/python2.7/site-packages/tornado/gen.py", line 1008, in run
        value = future.result()
      File "/opt/gridware/apps/binapps/anaconda/2.5.0/lib/python2.7/site-packages/tornado/concurrent.py", line 232, in result
        raise_exc_info(self._exc_info)
      File "<string>", line 3, in raise_exc_info
    RuntimeError: Restart failed
[E 13:27:50.700 NotebookApp] {
      "Origin": "http://localhost:8888", 
      "Content-Length": "0", 
      "Accept-Language": "en-GB,en-US;q=0.9,en;q=0.8", 
      "Accept-Encoding": "gzip, deflate, br", 
      "Host": "localhost:8888", 
      "Accept": "application/json, text/javascript, */*; q=0.01", 
      "User-Agent": "Mozilla/5.0 (Macintosh; Intel Mac OS X 10_12_6) AppleWebKit/537.36 (KHTML, like Gecko) Chrome/69.0.3497.100 Safari/537.36", 
      "Connection": "keep-alive", 
      "X-Requested-With": "XMLHttpRequest", 
      "Referer": "http://localhost:8888/notebooks/convergence_SES.ipynb", 
      "Cookie": "_xsrf=2|c0c4339f|d25562b6f7a8c093db45b97b9a55dcf9|1539702951; session=.eJwNzklqQzEQANG7aO1FS62efBmjniAEbHCyM7l7_rp4UJ_x-MpxH3qWKmPxogVs1Ru361SevMmgbFU2uCJNXBIqhMyRuq4yw0BOAUZmkDavQpcJJDtPJGZ7ECVFHWIlNbCKcC_SQ27EgnvcRvy8-_H7-q7n9WPFTS67aesEgcN4iSOwW8HbVHijYY-_f9oSNRs.W85Ljw.5jpYu3LBOUI8WUUnPQYlj3Z-Fko; username-localhost-8889=\"2|1:0|10:1540257795|23:username-localhost-8889|44:NWUxOWI0M2M2N2M0NGE0YjliNDEwZjFiMDg2NmU0N2U=|ff6fa490604537c659a8e156509a86b7e90b0be30ce1a9a0a1e9809fa110b2e2\""
    }
[E 13:27:50.700 NotebookApp] 500 POST /api/kernels/3f9cef16-4e2f-4483-b111-3f303e48d163/restart (10.110.1.41) 16048.70ms referer=http://localhost:8888/notebooks/convergence_SES.ipynb
[W 13:27:50.929 NotebookApp] Kernel deleted before session
[W 13:27:50.930 NotebookApp] 410 DELETE /api/sessions/9ad14b67-3b53-4898-bc6a-b0c6f2573fa5 (10.110.1.41) 1.93ms referer=http://localhost:8888/notebooks/convergence_SES.ipynb
[W 13:27:52.727 NotebookApp] Session not found: session_id=u'9ad14b67-3b53-4898-bc6a-b0c6f2573fa5'
[W 13:27:52.728 NotebookApp] 404 DELETE /api/sessions/9ad14b67-3b53-4898-bc6a-b0c6f2573fa5 (10.110.1.41) 1.42ms referer=http://localhost:8888/notebooks/convergence_SES.ipynb
[I 13:27:52.782 NotebookApp] Kernel started: 7171afe7-68df-425f-b6a4-d1d1b389784f
[I 13:29:00.890 NotebookApp] Saving file at /convergence_SES.ipynb
[I 15:04:08.086 NotebookApp] Kernel interrupted: 7171afe7-68df-425f-b6a4-d1d1b389784f
[I 15:04:22.696 NotebookApp] Saving file at /convergence_SES.ipynb
[I 15:04:26.836 NotebookApp] Kernel shutdown: 7171afe7-68df-425f-b6a4-d1d1b389784f
